Traceback (most recent call last):
  File "train.py", line 432, in <module>
    decaylr=args.decaylr,
  File "train.py", line 222, in run_training
    feed_dict={self.masterhandle: training_handle})
  File "/usr/local/lib/python2.7/dist-packages/tensorflow/python/client/session.py", line 905, in run
    run_metadata_ptr)
  File "/usr/local/lib/python2.7/dist-packages/tensorflow/python/client/session.py", line 1140, in _run
    feed_dict_tensor, options, run_metadata)
  File "/usr/local/lib/python2.7/dist-packages/tensorflow/python/client/session.py", line 1321, in _do_run
    run_metadata)
  File "/usr/local/lib/python2.7/dist-packages/tensorflow/python/client/session.py", line 1340, in _do_call
    raise type(e)(node_def, op, message)
tensorflow.python.framework.errors_impl.NotFoundError: /data/pascal_seg/training.tfrecords; No such file or directory
	 [[Node: IteratorGetNext = IteratorGetNext[output_shapes=[[?,512,512,3], [?,512,512]], output_types=[DT_UINT8, DT_INT32], _device="/job:localhost/replica:0/task:0/device:CPU:0"](IteratorFromStringHandle)]]

Caused by op u'IteratorGetNext', defined at:
  File "train.py", line 409, in <module>
    trainer.setup()
  File "train.py", line 313, in setup
    image_batch, self.annotation_batch = switching_iterator.get_next()
  File "/usr/local/lib/python2.7/dist-packages/tensorflow/python/data/ops/iterator_ops.py", line 366, in get_next
    name=name)), self._output_types,
  File "/usr/local/lib/python2.7/dist-packages/tensorflow/python/ops/gen_dataset_ops.py", line 1455, in iterator_get_next
    output_shapes=output_shapes, name=name)
  File "/usr/local/lib/python2.7/dist-packages/tensorflow/python/framework/op_def_library.py", line 787, in _apply_op_helper
    op_def=op_def)
  File "/usr/local/lib/python2.7/dist-packages/tensorflow/python/framework/ops.py", line 3290, in create_op
    op_def=op_def)
  File "/usr/local/lib/python2.7/dist-packages/tensorflow/python/framework/ops.py", line 1654, in __init__
    self._traceback = self._graph._extract_stack()  # pylint: disable=protected-access

NotFoundError (see above for traceback): /data/pascal_seg/training.tfrecords; No such file or directory
	 [[Node: IteratorGetNext = IteratorGetNext[output_shapes=[[?,512,512,3], [?,512,512]], output_types=[DT_UINT8, DT_INT32], _device="/job:localhost/replica:0/task:0/device:CPU:0"](IteratorFromStringHandle)]]

